Workbook
Name C_: #REF!
Name Critères_respectés: #REF!
Name P21_: Échantillon!$A$32

Sheet Échantillon
A1: Capgemini ♠ | B1: Grille RGAA 4.1.2
A2: Date
A3: Auditeur
A4: Client
A5: Service numérique
A6: Informations
A7: Pour rappel, les pages obligatoires dans un échantillon d'audit sont : - Page d'accueil - Page contact - Page mentions légale - Page « accessibilité » (page comprenant la déclaration d’accessibilité) - Page aide - Page plan du site - Page d’authentification
A9: Échantillon évalué
A11: N° page | B11: Titre de la page | C11: URL | D11: Eléments Transverses
A12: P01
A13: P02
A14: P03
A15: P04
A16: P05
A17: P06
A18: P07
A19: P08
A20: P09
A21: P10
A22: P11
A23: P12
... A51: P40

Sheet Synthèse
B1: =Échantillon!B1 -> Grille RGAA 4.1.2 | C1: | Synthèse des résultats
A3: Évaluation de taux conformité globale au RGAA | J3: Informations
A4: Le pourcentage de critères RGAA respectés s’obtient en divisant le nombre de critères conformes par le nombre de critères applicables (conformes + non conformes) Rappel sur les états de conformités du taux de conformité global au RGAA : - Totalement conforme : si 100 % des critères de contrôle sont respectés - Partiellement conforme : si au moins 50 % des critères de contrôle sont respectés - Non conforme : si moins de 50 % des critères de contrôle sont respectés | J4: Légende : - C : Conforme - Le critère est conforme pour l'ensemble des éléments de la page - NC : Non conforme - Le critère n'est pas conforme - NA : Non applicable - Ou bien aucun élément dans la page ne concerne le critère, ou bien le seul contenu qui concerne le critère est exempté, ou bien le seul contenu qui concerne le critère est soumis à dérogation et il propose une alternative numérique accessible - D : Dérogation - Critère dont la correction constituerait une charge disproportionnée ------------------------------------------------------------------------------------------------------------ - NT : Non testé - Le critère n'est pas testé. Ce statut sert à mesurer l'évolution de l'audit Un critère est jugé non conforme dans l'évaluation globale à partir du moment où il existe une page de l'échantillon pour laquelle ce critère n'est pas conforme.
D6: RGAA
A7: Etat de conformité | D7: =IF(D10+E10=0,"En attente de données",IF(D8=100%,"Totalement conforme",IF(D8<50%,"Non conforme",IF(D8>=50%,"Partiellement conforme")))) -> En attente de données
A8: Taux de conformité global | D8: ='Visualisation d''ensemble'!AW6 -> En attente de données
A9: Total critères | D9: C | E9: NC | F9: NA | G9: D
D10: ='Visualisation d''ensemble'!AW3 -> 0 | E10: ='Visualisation d''ensemble'!AW4 -> 0 | F10: ='Visualisation d''ensemble'!AW5 -> 0 | G10: ='Visualisation d''ensemble'!AZ6 -> 0
A11: Taux moyen de conformité du service | H11: =IF(C14>0,AVERAGE(_xlfn.ANCHORARRAY(H15)),"")
A13: RGAA : résultats pas pages
A14: Nombre de pages auditées : | C14: =COUNT(H15:H36) -> 0 | D14: C | E14: NC | F14: NA | G14: D | H14: Taux par page
A15: =Échantillon!A12 -> P01 | B15: =IF(VLOOKUP(A15,Échantillon!A11:D51,2,FALSE)="","",VLOOKUP(A15,Échantillon!A11:D51,2,FALSE)) | D15: {=TRANSPOSE('Visualisation d''ensemble'!F3:AS3)} -> 0 | E15: {=TRANSPOSE('Visualisation d''ensemble'!F4:AS4)} -> 0 | F15: {=TRANSPOSE('Visualisation d''ensemble'!F5:AS5)} -> 0 | G15: {=TRANSPOSE('Visualisation d''ensemble'!BA6:CN6)} -> 0 | H15: {=TRANSPOSE('Visualisation d''ensemble'!F6:AS6)}
A16: =Échantillon!A13 -> P02 | B16: =IF(VLOOKUP(A16,Échantillon!A12:D52,2,FALSE)="","",VLOOKUP(A16,Échantillon!A12:D52,2,FALSE)) | D16: 0 | E16: 0 | F16: 0 | G16: 0
A17: =Échantillon!A14 -> P03 | B17: =IF(VLOOKUP(A17,Échantillon!A13:D53,2,FALSE)="","",VLOOKUP(A17,Échantillon!A13:D53,2,FALSE)) | D17: 0 | E17: 0 | F17: 0 | G17: 0
A18: =Échantillon!A15 -> P04 | B18: =IF(VLOOKUP(A18,Échantillon!A14:D54,2,FALSE)="","",VLOOKUP(A18,Échantillon!A14:D54,2,FALSE)) | D18: 0 | E18: 0 | F18: 0 | G18: 0
A19: =Échantillon!A16 -> P05 | B19: =IF(VLOOKUP(A19,Échantillon!A15:D55,2,FALSE)="","",VLOOKUP(A19,Échantillon!A15:D55,2,FALSE)) | D19: 0 | E19: 0 | F19: 0 | G19: 0
A20: =Échantillon!A17 -> P06 | B20: =IF(VLOOKUP(A20,Échantillon!A16:D56,2,FALSE)="","",VLOOKUP(A20,Échantillon!A16:D56,2,FALSE)) | D20: 0 | E20: 0 | F20: 0 | G20: 0
A21: =Échantillon!A18 -> P07 | B21: =IF(VLOOKUP(A21,Échantillon!A17:D57,2,FALSE)="","",VLOOKUP(A21,Échantillon!A17:D57,2,FALSE)) | D21: 0 | E21: 0 | F21: 0 | G21: 0
A22: =Échantillon!A19 -> P08 | B22: =IF(VLOOKUP(A22,Échantillon!A18:D58,2,FALSE)="","",VLOOKUP(A22,Échantillon!A18:D58,2,FALSE)) | D22: 0 | E22: 0 | F22: 0 | G22: 0
A23: =Échantillon!A20 -> P09 | B23: =IF(VLOOKUP(A23,Échantillon!A19:D59,2,FALSE)="","",VLOOKUP(A23,Échantillon!A19:D59,2,FALSE)) | D23: 0 | E23: 0 | F23: 0 | G23: 0
A24: =Échantillon!A21 -> P10 | B24: =IF(VLOOKUP(A24,Échantillon!A20:D60,2,FALSE)="","",VLOOKUP(A24,Échantillon!A20:D60,2,FALSE)) | D24: 0 | E24: 0 | F24: 0 | G24: 0
A25: =Échantillon!A22 -> P11 | B25: =IF(VLOOKUP(A25,Échantillon!A21:D61,2,FALSE)="","",VLOOKUP(A25,Échantillon!A21:D61,2,FALSE)) | D25: 0 | E25: 0 | F25: 0 | G25: 0
A26: =Échantillon!A23 -> P12 | B26: =IF(VLOOKUP(A26,Échantillon!A22:D62,2,FALSE)="","",VLOOKUP(A26,Échantillon!A22:D62,2,FALSE)) | D26: 0 | E26: 0 | F26: 0 | G26: 0
A27: =Échantillon!A24 -> P13 | B27: =IF(VLOOKUP(A27,Échantillon!A23:D63,2,FALSE)="","",VLOOKUP(A27,Échantillon!A23:D63,2,FALSE)) | D27: 0 | E27: 0 | F27: 0 | G27: 0
... A54: =Échantillon!A51 -> P40 | B54: =IF(VLOOKUP(A54,Échantillon!A50:D90,2,FALSE)="","",VLOOKUP(A54,Échantillon!A50:D90,2,FALSE)) | D54: 0 | E54: 0 | F54: 0 | G54: 0

Sheet Critères et tests
A1: =Échantillon!$A$1 -> Capgemini ♠ | B1: | Liste des critères RGAA 4.1.2
A2: n°critères | B2: Thématique | C2: Niveau WCAG | D2: Référenciel | E2: Intitulé des critères | F2: Statut et nombre de pages où le critère est non conforme | G2: Déficiences concernées | H2: Planification des correctifs | I2: Impacts utilisateurs | J2: Méthodologie de test du RGAA
A3: 1.1 | B3: IMAGES | C3: A | D3: RGAA | E3: Chaque image porteuse d’information a-t-elle une alternative textuelle ? | F3: ='Visualisation d''ensemble'!$AW8&CHAR(10)&'Visualisation d''ensemble'!$AU8 -> NT 0 | G3: Aveugles Déficients visuels | H3: Principale | I3: Majeur | J3: Tests et références du critère 1.1
A4: 1.2 | B4: IMAGES | C4: A | D4: RGAA | E4: Chaque image de décoration est-elle correctement ignorée par les technologies d’assistance ? | F4: ='Visualisation d''ensemble'!$AW9&CHAR(10)&'Visualisation d''ensemble'!$AU9 -> NT 0 | G4: Aveugles Déficients visuels | H4: Faible à important | I4: Faible à fort | J4: Tests et références du critère 1.2
A5: 1.3 | B5: IMAGES | C5: A | D5: RGAA | E5: Pour chaque image porteuse d'information ayant une alternative textuelle, cette alternative est-elle pertinente (hors cas particuliers) ? | F5: ='Visualisation d''ensemble'!$AW10&CHAR(10)&'Visualisation d''ensemble'!$AU10 -> NT 0 | G5: Aveugles Déficients visuels | H5: Principale | I5: Majeur | J5: Tests et références du critère 1.3
A6: 1.4 | B6: IMAGES | C6: A | D6: RGAA | E6: Pour chaque image utilisée comme CAPTCHA ou comme image-test, ayant une alternative textuelle, cette alternative permet-elle d’identifier la nature et la fonction de l’image ? | F6: ='Visualisation d''ensemble'!$AW11&CHAR(10)&'Visualisation d''ensemble'!$AU11 -> NT 0 | G6: Aveugles, Déficients visuels, Dyslexiques | H6: Principale | I6: Majeur | J6: Tests et références du critère 1.4
A7: 1.5 | B7: IMAGES | C7: A | D7: RGAA | E7: Pour chaque image utilisée comme CAPTCHA, une solution d’accès alternatif au contenu ou à la fonction du CAPTCHA est-elle présente ? | F7: ='Visualisation d''ensemble'!$AW12&CHAR(10)&'Visualisation d''ensemble'!$AU12 -> NT 0 | G7: Aveugles, Déficients visuels, Dyslexiques | H7: Principale | I7: Majeur | J7: Tests et références du critère 1.5
A8: 1.6 | B8: IMAGES | C8: A | D8: RGAA | E8: Chaque image porteuse d’information a-t-elle, si nécessaire, une description détaillée ? | F8: ='Visualisation d''ensemble'!$AW13&CHAR(10)&'Visualisation d''ensemble'!$AU13 -> NT 0 | G8: Aveugles, Déficients visuels, Dyslexiques | H8: Principale | I8: Majeur | J8: Tests et références du critère 1.6
A9: 1.7 | B9: IMAGES | C9: A | D9: RGAA | E9: Pour chaque image porteuse d’information ayant une description détaillée, cette description est-elle pertinente ? | F9: ='Visualisation d''ensemble'!$AW14&CHAR(10)&'Visualisation d''ensemble'!$AU14 -> NT 0 | G9: Aveugles, Déficients visuels, Dyslexiques | H9: Principale | I9: Majeur | J9: Tests et références du critère 1.7
A10: 1.8 | B10: IMAGES | C10: AA | D10: RGAA | E10: Chaque image texte porteuse d’information, en l’absence d’un mécanisme de remplacement, doit si possible être remplacée par du texte stylé. Cette règle est-elle respectée (hors cas particuliers) ? | F10: ='Visualisation d''ensemble'!$AW15&CHAR(10)&'Visualisation d''ensemble'!$AU15 -> NT 0 | G10: Aveugles, Déficients visuels, Dyslexiques | H10: Moyen à important | I10: Modéré à fort | J10: Tests et références du critère 1.8
A11: 1.9 | B11: IMAGES | C11: A | D11: RGAA | E11: Chaque légende d’image est-elle, si nécessaire, correctement reliée à l’image correspondante ? | F11: ='Visualisation d''ensemble'!$AW16&CHAR(10)&'Visualisation d''ensemble'!$AU16 -> NT 0 | G11: Aveugles | H11: Important à principale | I11: Fort à majeur | J11: Tests et références du critère 1.9
A12: 2.1 | B12: CADRE | C12: A | D12: RGAA | E12: Chaque cadre a-t-il un titre de cadre ? | F12: ='Visualisation d''ensemble'!$AW17&CHAR(10)&'Visualisation d''ensemble'!$AU17 -> NT 0 | G12: Aveugles | H12: Important à principale | I12: Faible à fort | J12: Tests et références du critère 2.1
A13: 2.2 | B13: CADRE | C13: A | D13: RGAA | E13: Pour chaque cadre ayant un titre de cadre, ce titre de cadre est-il pertinent ? | F13: ='Visualisation d''ensemble'!$AW18&CHAR(10)&'Visualisation d''ensemble'!$AU18 -> NT 0 | G13: Aveugles | H13: Faible à important | I13: Faible à fort | J13: Tests et références du critère 2.2
A14: 3.1 | B14: COULEURS | C14: A | D14: RGAA | E14: Dans chaque page web, l’information ne doit pas être donnée uniquement par la couleur. Cette règle est-elle respectée ? | F14: ='Visualisation d''ensemble'!$AW19&CHAR(10)&'Visualisation d''ensemble'!$AU19 -> NT 0 | G14: Aveugles Déficients visuels | H14: Faible à important | I14: Fort à majeur | J14: Tests et références du critère 3.1
... A44: 7.5 | B44: SCRIPTS | C44: AA | D44: RGAA | E44: Dans chaque page web, les messages de statut sont-ils correctement restitués par les technologies d’assistance ? | F44: ='Visualisation d''ensemble'!$AW49&CHAR(10)&'Visualisation d''ensemble'!$AU49 -> NT 0 | G44: Aveugles Déficients visuels | H44: Principale | I44: Fort à majeur | J44: Tests et références du critère 7.5
A45: 8.1 | B45: =UPPER("éLéMENTS OBLIGATOIRES") -> ÉLÉMENTS OBLIGATOIRES | C45: A | D45: RGAA | E45: Chaque page web est-elle définie par un type de document ? | F45: ='Visualisation d''ensemble'!$AW50&CHAR(10)&'Visualisation d''ensemble'!$AU50 -> NT 0 | G45: Tous les utilisateurs | H45: Normal | I45: Faible à modéré | J45: Tests et références du critère 8.1
A46: 8.2 | B46: =UPPER("éLéMENTS OBLIGATOIRES") -> ÉLÉMENTS OBLIGATOIRES | C46: A | D46: RGAA | E46: Pour chaque page web, le code source généré est-il valide selon le type de document spécifié (hors cas particuliers) ? | F46: ='Visualisation d''ensemble'!$AW51&CHAR(10)&'Visualisation d''ensemble'!$AU51 -> NT 0 | G46: Tous les utilisateurs | H46: Normal | I46: Faible à modéré | J46: Tests et références du critère 8.2
A47: 8.3 | B47: =UPPER("éLéMENTS OBLIGATOIRES") -> ÉLÉMENTS OBLIGATOIRES | C47: A | D47: RGAA | E47: Dans chaque page web, la langue par défaut est-elle présente ? | F47: ='Visualisation d''ensemble'!$AW52&CHAR(10)&'Visualisation d''ensemble'!$AU52 -> NT 0 | G47: Aveugles | H47: Principale | I47: Fort | J47: Tests et références du critère 8.3
A48: 8.4 | B48: =UPPER("éLéMENTS OBLIGATOIRES") -> ÉLÉMENTS OBLIGATOIRES | C48: A | D48: RGAA | E48: Pour chaque page web ayant une langue par défaut, le code de langue est-il pertinent ? | F48: ='Visualisation d''ensemble'!$AW53&CHAR(10)&'Visualisation d''ensemble'!$AU53 -> NT 0 | G48: Aveugles | H48: Principale | I48: Fort | J48: Tests et références du critère 8.4
A49: 8.5 | B49: =UPPER("éLéMENTS OBLIGATOIRES") -> ÉLÉMENTS OBLIGATOIRES | C49: A | D49: RGAA | E49: Chaque page web a-t-elle un titre de page ? | F49: ='Visualisation d''ensemble'!$AW54&CHAR(10)&'Visualisation d''ensemble'!$AU54 -> NT 0 | G49: Aveugles Handicapés moteurs | H49: Principale | I49: Fort à majeur | J49: Tests et références du critère 8.5
A50: 8.6 | B50: =UPPER("éLéMENTS OBLIGATOIRES") -> ÉLÉMENTS OBLIGATOIRES | C50: A | D50: RGAA | E50: Pour chaque page web ayant un titre de page, ce titre est-il pertinent ? | F50: ='Visualisation d''ensemble'!$AW55&CHAR(10)&'Visualisation d''ensemble'!$AU55 -> NT 0 | G50: Aveugles Handicapés moteurs | H50: Important à principale | I50: Fort à majeur | J50: Tests et références du critère 8.6
A51: 8.7 | B51: =UPPER("éLéMENTS OBLIGATOIRES") -> ÉLÉMENTS OBLIGATOIRES | C51: AA | D51: RGAA | E51: Dans chaque page web, chaque changement de langue est-il indiqué dans le code source (hors cas particuliers) ? | F51: ='Visualisation d''ensemble'!$AW56&CHAR(10)&'Visualisation d''ensemble'!$AU56 -> NT 0 | G51: Aveugles | H51: Important à principale | I51: Fort | J51: Tests et références du critère 8.7
A52: 8.8 | B52: =UPPER("éLéMENTS OBLIGATOIRES") -> ÉLÉMENTS OBLIGATOIRES | C52: AA | D52: RGAA | E52: Dans chaque page web, le code de langue de chaque changement de langue est-il valide et pertinent ? | F52: ='Visualisation d''ensemble'!$AW57&CHAR(10)&'Visualisation d''ensemble'!$AU57 -> NT 0 | G52: Aveugles | H52: Important à principale | I52: Fort | J52: Tests et références du critère 8.8
A53: 8.9 | B53: =UPPER("éLéMENTS OBLIGATOIRES") -> ÉLÉMENTS OBLIGATOIRES | C53: A | D53: RGAA | E53: Dans chaque page web, les balises ne doivent pas être utilisées uniquement à des fins de présentation. Cette règle est-elle respectée ? | F53: ='Visualisation d''ensemble'!$AW58&CHAR(10)&'Visualisation d''ensemble'!$AU58 -> NT 0 | G53: Aveugles | H53: Important | I53: Faible à majeur | J53: Tests et références du critère 8.9
A54: 8.10 | B54: =UPPER("éLéMENTS OBLIGATOIRES") -> ÉLÉMENTS OBLIGATOIRES | C54: A | D54: RGAA | E54: Dans chaque page web, les changements du sens de lecture sont-ils signalés ? | F54: ='Visualisation d''ensemble'!$AW59&CHAR(10)&'Visualisation d''ensemble'!$AU59 -> NT 0 | G54: Aveugles | H54: Important à principale | I54: Fort | J54: Tests et références du critère 8.10
A55: 9.1 | B55: STRUCTURATION | C55: A | D55: RGAA | E55: Dans chaque page web, l’information est-elle structurée par l’utilisation appropriée de titres ? | F55: ='Visualisation d''ensemble'!$AW60&CHAR(10)&'Visualisation d''ensemble'!$AU60 -> NT 0 | G55: Aveugles Handicapés moteurs | H55: Important à principale | I55: Modéré à fort | J55: Tests et références du critère 9.1
A56: 9.2 | B56: STRUCTURATION | C56: A | D56: RGAA | E56: Dans chaque page web, la structure du document est-elle cohérente (hors cas particuliers) ? | F56: ='Visualisation d''ensemble'!$AW61&CHAR(10)&'Visualisation d''ensemble'!$AU61 -> NT 0 | G56: Aveugles Handicapés moteurs | H56: Faible à modéré | I56: Modéré à fort | J56: Tests et références du critère 9.2
A57: 9.3 | B57: STRUCTURATION | C57: A | D57: RGAA | E57: Dans chaque page web, chaque liste est-elle correctement structurée ? | F57: ='Visualisation d''ensemble'!$AW62&CHAR(10)&'Visualisation d''ensemble'!$AU62 -> NT 0 | G57: Aveugles | H57: Faible à modéré | I57: Modéré à fort | J57: Tests et références du critère 9.3
A58: 9.4 | B58: STRUCTURATION | C58: A | D58: RGAA | E58: Dans chaque page web, chaque citation est-elle correctement indiquée ? | F58: ='Visualisation d''ensemble'!$AW63&CHAR(10)&'Visualisation d''ensemble'!$AU63 -> NT 0 | G58: Aveugles | H58: Important | I58: Faible à fort | J58: Tests et références du critère 9.4
A59: 10.1 | B59: =UPPER("PRéSENTATION") -> PRÉSENTATION | C59: A | D59: RGAA | E59: Dans le site web, des feuilles de styles sont-elles utilisées pour contrôler la présentation de l’information ? | F59: ='Visualisation d''ensemble'!$AW64&CHAR(10)&'Visualisation d''ensemble'!$AU64 -> NT 0 | G59: Déficients visuels Déficient cognitifs | H59: Important | I59: Fort à majeur | J59: Tests et références du critère 10.1
A60: 10.2 | B60: =UPPER("PRéSENTATION") -> PRÉSENTATION | C60: A | D60: RGAA | E60: Dans chaque page web, le contenu visible porteur d’information reste-t-il présent lorsque les feuilles de styles sont désactivées ? | F60: ='Visualisation d''ensemble'!$AW65&CHAR(10)&'Visualisation d''ensemble'!$AU65 -> NT 0 | G60: Aveugles | H60: Important à principale | I60: Fort à majeur | J60: Tests et références du critère 10.2
A61: 10.3 | B61: =UPPER("PRéSENTATION") -> PRÉSENTATION | C61: A | D61: RGAA | E61: Dans chaque page web, l’information reste-t-elle compréhensible lorsque les feuilles de styles sont désactivées ? | F61: ='Visualisation d''ensemble'!$AW66&CHAR(10)&'Visualisation d''ensemble'!$AU66 -> NT 0 | G61: Aveugles | H61: Important à principale | I61: Fort à majeur | J61: Tests et références du critère 10.3
A62: 10.4 | B62: =UPPER("PRéSENTATION") -> PRÉSENTATION | C62: AA | D62: RGAA | E62: Dans chaque page web, le texte reste-t-il lisible lorsque la taille des caractères est augmentée jusqu’à 200%, au moins (hors cas particuliers) ? | F62: ='Visualisation d''ensemble'!$AW67&CHAR(10)&'Visualisation d''ensemble'!$AU67 -> NT 0 | G62: Déficients visuels | H62: Important | I62: Fort à majeur | J62: Tests et références du critère 10.4
A63: 10.5 | B63: =UPPER("PRéSENTATION") -> PRÉSENTATION | C63: AA | D63: RGAA | E63: Dans chaque page web, les déclarations CSS de couleurs de fond d’élément et de police sont-elles correctement utilisées ? | F63: ='Visualisation d''ensemble'!$AW68&CHAR(10)&'Visualisation d''ensemble'!$AU68 -> NT 0 | G63: Déficients visuels | H63: Important | I63: Fort à majeur | J63: Tests et références du critère 10.5
A64: 10.6 | B64: =UPPER("PRéSENTATION") -> PRÉSENTATION | C64: A | D64: RGAA | E64: Dans chaque page web, chaque lien dont la nature n’est pas évidente est-il visible par rapport au texte environnant ? | F64: ='Visualisation d''ensemble'!$AW69&CHAR(10)&'Visualisation d''ensemble'!$AU69 -> NT 0 | G64: Déficients visuels | H64: Faible à majeur | I64: Fort | J64: Tests et références du critère 10.6
A65: 10.7 | B65: =UPPER("PRéSENTATION") -> PRÉSENTATION | C65: A | D65: RGAA | E65: Dans chaque page web, pour chaque élément recevant le focus, la prise de focus est-elle visible ? | F65: ='Visualisation d''ensemble'!$AW70&CHAR(10)&'Visualisation d''ensemble'!$AU70 -> NT 0 | G65: Handicapés moteurs | H65: Important | I65: Fort à majeur | J65: Tests et références du critère 10.7
A66: 10.8 | B66: =UPPER("PRéSENTATION") -> PRÉSENTATION | C66: A | D66: RGAA | E66: Pour chaque page web, les contenus cachés ont-ils vocation à être ignorés par les technologies d’assistance ? | F66: ='Visualisation d''ensemble'!$AW71&CHAR(10)&'Visualisation d''ensemble'!$AU71 -> NT 0 | G66: Aveugles Déficients visuels | H66: Moyen à important | I66: Majeur | J66: Tests et références du critère 10.8
A67: 10.9 | B67: =UPPER("PRéSENTATION") -> PRÉSENTATION | C67: A | D67: RGAA | E67: Dans chaque page web, l’information ne doit pas être donnée uniquement par la forme, taille ou position. Cette règle est-elle respectée ? | F67: ='Visualisation d''ensemble'!$AW72&CHAR(10)&'Visualisation d''ensemble'!$AU72 -> NT 0 | G67: Aveugles | H67: Moyen à important | I67: Majeur | J67: Tests et références du critère 10.9
A68: 10.10 | B68: =UPPER("PRéSENTATION") -> PRÉSENTATION | C68: A | D68: RGAA | E68: Dans chaque page web, l’information ne doit pas être donnée par la forme, taille ou position uniquement. Cette règle est-elle implémentée de façon pertinente ? | F68: ='Visualisation d''ensemble'!$AW73&CHAR(10)&'Visualisation d''ensemble'!$AU73 -> NT 0 | G68: Aveugles | H68: Moyen à important | I68: Majeur | J68: Tests et références du critère 10.10
A69: 10.11 | B69: =UPPER("PRéSENTATION") -> PRÉSENTATION | C69: AA | D69: RGAA | E69: Pour chaque page web, les contenus peuvent-ils être présentés sans perte d’information ou de fonctionnalité et sans avoir recours soit à un défilement vertical pour une fenêtre ayant une hauteur de 256 px, soit à un défilement horizontal pour une fenêtre ayant une largeur de 320 px (hors cas particuliers) ? | F69: ='Visualisation d''ensemble'!$AW74&CHAR(10)&'Visualisation d''ensemble'!$AU74 -> NT 0 | G69: Déficients visuels Handicapés moteurs . | H69: Faible à important | I69: Fort à majeur | J69: Tests et références du critère 10.11
...

Sheet Visualisation d'ensemble
A1: =Échantillon!A1 -> Capgemini ♠ | B1: | Visualisation de l'ensemble des critères & dérogations
A2: Viewing all criteria | F2: Evaluation des critères | BA2: Dérogations
A3: Résultats RGAA | E3: C | F3: =COUNTIFS(F7:F138,"C*",$E7:$E138,"RGAA") -> 0 | G3: =COUNTIFS(G7:G138,"C*",$E7:$E138,"RGAA") -> 0 | H3: =COUNTIFS(H7:H138,"C*",$E7:$E138,"RGAA") -> 0 | I3: =COUNTIFS(I7:I138,"C*",$E7:$E138,"RGAA") -> 0 | J3: =COUNTIFS(J7:J138,"C*",$E7:$E138,"RGAA") -> 0 | K3: =COUNTIFS(K7:K138,"C*",$E7:$E138,"RGAA") -> 0 | L3: =COUNTIFS(L7:L138,"C*",$E7:$E138,"RGAA") -> 0 | M3: =COUNTIFS(M7:M138,"C*",$E7:$E138,"RGAA") -> 0 | ... AS3: =COUNTIFS(AS7:AS138,"C*",$E7:$E138,"RGAA") -> 0 | AT3: Total C | AW3: =COUNTIFS(AW7:AW138,"C*",$E7:$E138,"RGAA") -> 0
E4: NC | F4: =COUNTIFS(F7:F138,"NC*",$E7:$E138,"RGAA") -> 0 | G4: =COUNTIFS(G7:G138,"NC*",$E7:$E138,"RGAA") -> 0 | H4: =COUNTIFS(H7:H138,"NC*",$E7:$E138,"RGAA") -> 0 | I4: =COUNTIFS(I7:I138,"NC*",$E7:$E138,"RGAA") -> 0 | J4: =COUNTIFS(J7:J138,"NC*",$E7:$E138,"RGAA") -> 0 | K4: =COUNTIFS(K7:K138,"NC*",$E7:$E138,"RGAA") -> 0 | L4: =COUNTIFS(L7:L138,"NC*",$E7:$E138,"RGAA") -> 0 | M4: =COUNTIFS(M7:M138,"NC*",$E7:$E138,"RGAA") -> 0 | ... AS4: =COUNTIFS(AS7:AS138,"NC*",$E7:$E138,"RGAA") -> 0 | AT4: Total NC | AW4: =COUNTIFS(AW7:AW138,"NC*",$E7:$E138,"RGAA") -> 0
E5: NA | F5: =COUNTIFS(F7:F138,"NA*",$E7:$E138,"RGAA") -> 0 | G5: =COUNTIFS(G7:G138,"NA*",$E7:$E138,"RGAA") -> 0 | H5: =COUNTIFS(H7:H138,"NA*",$E7:$E138,"RGAA") -> 0 | I5: =COUNTIFS(I7:I138,"NA*",$E7:$E138,"RGAA") -> 0 | J5: =COUNTIFS(J7:J138,"NA*",$E7:$E138,"RGAA") -> 0 | K5: =COUNTIFS(K7:K138,"NA*",$E7:$E138,"RGAA") -> 0 | L5: =COUNTIFS(L7:L138,"NA*",$E7:$E138,"RGAA") -> 0 | M5: =COUNTIFS(M7:M138,"NA*",$E7:$E138,"RGAA") -> 0 | ... AS5: =COUNTIFS(AS7:AS138,"NA*",$E7:$E138,"RGAA") -> 0 | AT5: Total NA | AW5: =COUNTIFS(AW7:AW138,"NA",$E7:$E138,"RGAA") -> 0
A6: Taux de conformité par page | E6: =IF(COUNT(F6:AS6)>0,AVERAGE(F6:AS6),"-") -> - | F6: =IFERROR(F3/(F3+F4), "") | G6: =IFERROR(G3/(G3+G4), "") | H6: =IFERROR(H3/(H3+H4), "") | I6: =IFERROR(I3/(I3+I4), "") | J6: =IFERROR(J3/(J3+J4), "") | K6: =IFERROR(K3/(K3+K4), "") | L6: =IFERROR(L3/(L3+L4), "") | M6: =IFERROR(M3/(M3+M4), "") | ... AS6: =IFERROR(AS3/(AS3+AS4), "") | AT6: Taux global RGAA | AW6: =IF(AW3+AW4=0,"En attente de données",AW3/(AW3+AW4)) -> En attente de données | AY6: Derog | AZ6: =SUM(BA6:CN6) -> 0 | BA6: =COUNTIFS(BA7:BA138,"Oui",$E7:$E138,"RGAA") -> 0 | BB6: =COUNTIFS(BB7:BB138,"Oui",$E7:$E138,"RGAA") -> 0 | BC6: =COUNTIFS(BC7:BC138,"Oui",$E7:$E138,"RGAA") -> 0 | BD6: =COUNTIFS(BD7:BD138,"Oui",$E7:$E138,"RGAA") -> 0 | BE6: =COUNTIFS(BE7:BE138,"Oui",$E7:$E138,"RGAA") -> 0 | BF6: =COUNTIFS(BF7:BF138,"Oui",$E7:$E138,"RGAA") -> 0 | BG6: =COUNTIFS(BG7:BG138,"Oui",$E7:$E138,"RGAA") -> 0 | BH6: =COUNTIFS(BH7:BH138,"Oui",$E7:$E138,"RGAA") -> 0 | ... CN6: =COUNTIFS(CN7:CN138,"Oui",$E7:$E138,"RGAA") -> 0
A7: ='Critères et tests'!B2 -> Thématique | B7: ='Critères et tests'!$A2 -> n°critères | C7: ='Critères et tests'!E2 -> Intitulé des critères | D7: ='Critères et tests'!$C2 -> Niveau WCAG | F7: P01 | G7: P02 | H7: P03 | I7: P04 | J7: P05 | K7: P06 | L7: P07 | M7: P08 | N7: P09 | O7: P10 | P7: P11 | Q7: P12 | R7: P13 | S7: P14 | T7: P15 | U7: P16 | V7: P17 | W7: P18 | X7: P19 | Y7: P20 | Z7: P21 | AA7: P22 | AB7: P23 | AC7: P24 | AD7: P25 | AE7: P26 | AF7: P27 | AG7: P28 | AH7: P29 | AI7: P30 | AJ7: P31 | AK7: P32 | AL7: P33 | AM7: P34 | AN7: P35 | AO7: P36 | AP7: P37 | AQ7: P38 | AR7: P39 | AS7: P40 | AT7: C | AU7: NC | AV7: NA | AW7: Global | BA7: P01 | BB7: P02 | BC7: P03 | BD7: P04 | BE7: P05 | BF7: P06 | BG7: P07 | BH7: P08 | BI7: P09 | BJ7: P10 | BK7: P11 | BL7: P12 | BM7: P13 | BN7: P14 | BO7: P15 | BP7: P16 | BQ7: P17 | BR7: P18 | BS7: P19 | BT7: P20 | BU7: P21 | BV7: P22 | BW7: P23 | BX7: P24 | BY7: P25 | BZ7: P26 | CA7: P27 | CB7: P28 | CC7: P29 | CD7: P30 | CE7: P31 | CF7: P32 | CG7: P33 | CH7: P34 | CI7: P35 | CJ7: P36 | CK7: P37 | CL7: P38 | CM7: P39 | CN7: P40
A8: ='Critères et tests'!B3 -> IMAGES | B8: ='Critères et tests'!$A3 -> 1.1 | C8: =VLOOKUP(B8,'Critères et tests'!$1:$1048576,5,FALSE) -> Chaque image porteuse d’information a-t-elle une alternative textuelle ? | D8: ='Critères et tests'!$C3 -> A | E8: RGAA | F8: =IF('P01'!$E$4>"",'P01'!$E$4&" "&CHAR(10)&'P01'!$F$4,'P01'!$E$4) -> 0 | G8: =IF('P02'!$E4>"",'P02'!$E4&" "&CHAR(10)&'P02'!$F4,'P02'!$E4) -> 0 | H8: =IF('P03'!$E4>"",'P03'!$E4&" "&CHAR(10)&'P03'!$F4,'P03'!$E4) -> 0 | I8: =IF('P04'!$E4>"",'P04'!$E4&" "&CHAR(10)&'P04'!$F4,'P04'!$E4) -> 0 | J8: =IF('P05'!$E4>"",'P05'!$E4&" "&CHAR(10)&'P05'!$F4,'P05'!$E4) -> 0 | K8: =IF('P06'!$E4>"",'P06'!$E4&" "&CHAR(10)&'P06'!$F4,'P06'!$E4) -> 0 | L8: =IF('P07'!$E4>"",'P07'!$E4&" "&CHAR(10)&'P07'!$F4,'P07'!$E4) -> 0 | M8: =IF('P08'!$E4>"",'P08'!$E4&" "&CHAR(10)&'P08'!$F4,'P08'!$E4) -> 0 | N8: =IF('P09'!$E4>"",'P09'!$E4&" "&CHAR(10)&'P09'!$F4,'P09'!$E4) -> 0 | O8: =IF('P10'!$E4>"",'P10'!$E4&" "&CHAR(10)&'P10'!$F4,'P10'!$E4) -> 0 | P8: =IF('P11'!$E4>"",'P11'!$E4&" "&CHAR(10)&'P11'!$F4,'P11'!$E4) -> 0 | Q8: =IF('P12'!$E4>"",'P12'!$E4&" "&CHAR(10)&'P12'!$F4,'P12'!$E4) -> 0 | R8: =IF('P13'!$E4>"",'P13'!$E4&" "&CHAR(10)&'P13'!$F4,'P13'!$E4) -> 0 | S8: =IF('P14'!$E4>"",'P14'!$E4&" "&CHAR(10)&'P14'!$F4,'P14'!$E4) -> 0 | T8: =IF('P15'!$E4>"",'P15'!$E4&" "&CHAR(10)&'P15'!$F4,'P15'!$E4) -> 0 | U8: =IF('P16'!$E4>"",'P16'!$E4&" "&CHAR(10)&'P16'!$F4,'P16'!$E4) -> 0 | V8: =IF('P17'!$E4>"",'P17'!$E4&" "&CHAR(10)&'P17'!$F4,'P17'!$E4) -> 0 | W8: =IF('P18'!$E4>"",'P18'!$E4&" "&CHAR(10)&'P18'!$F4,'P18'!$E4) -> 0 | X8: =IF('P19'!$E4>"",'P19'!$E4&" "&CHAR(10)&'P19'!$F4,'P19'!$E4) -> 0 | Y8: =IF('P20'!$E4>"",'P20'!$E4&" "&CHAR(10)&'P20'!$F4,'P20'!$E4) -> 0 | Z8: =IF('P21'!$E4>"",'P21'!$E4&" "&CHAR(10)&'P21'!$F4,'P21'!$E4) -> 0 | AA8: =IF('P22'!$E4>"",'P22'!$E4&" "&CHAR(10)&'P22'!$F4,'P22'!$E4) -> 0 | AB8: =IF('P23'!$E4>"",'P23'!$E4&" "&CHAR(10)&'P23'!$F4,'P23'!$E4) -> 0 | AC8: =IF('P24'!$E4>"",'P24'!$E4&" "&CHAR(10)&'P24'!$F4,'P24'!$E4) -> 0 | AD8: =IF('P25'!$E4>"",'P25'!$E4&" "&CHAR(10)&'P25'!$F4,'P25'!$E4) -> 0 | AE8: =IF('P26'!$E4>"",'P26'!$E4&" "&CHAR(10)&'P26'!$F4,'P26'!$E4) -> 0 | AF8: =IF('P27'!$E4>"",'P27'!$E4&" "&CHAR(10)&'P27'!$F4,'P27'!$E4) -> 0 | AG8: =IF('P28'!$E4>"",'P28'!$E4&" "&CHAR(10)&'P28'!$F4,'P28'!$E4) -> 0 | AH8: =IF('P29'!$E4>"",'P29'!$E4&" "&CHAR(10)&'P29'!$F4,'P29'!$E4) -> 0 | AI8: =IF('P30'!$E4>"",'P30'!$E4&" "&CHAR(10)&'P30'!$F4,'P30'!$E4) -> 0 | AJ8: =IF('P31'!$E4>"",'P31'!$E4&" "&CHAR(10)&'P31'!$F4,'P31'!$E4) -> 0 | AK8: =IF('P32'!$E4>"",'P32'!$E4&" "&CHAR(10)&'P32'!$F4,'P32'!$E4) -> 0 | AL8: =IF('P33'!$E4>"",'P33'!$E4&" "&CHAR(10)&'P33'!$F4,'P33'!$E4) -> 0 | AM8: =IF('P34'!$E4>"",'P34'!$E4&" "&CHAR(10)&'P34'!$F4,'P34'!$E4) -> 0 | AN8: =IF('P35'!$E4>"",'P35'!$E4&" "&CHAR(10)&'P35'!$F4,'P35'!$E4) -> 0 | AO8: =IF('P36'!$E4>"",'P36'!$E4&" "&CHAR(10)&'P36'!$F4,'P36'!$E4) -> 0 | AP8: =IF('P37'!$E4>"",'P37'!$E4&" "&CHAR(10)&'P37'!$F4,'P37'!$E4) -> 0 | AQ8: =IF('P38'!$E4>"",'P38'!$E4&" "&CHAR(10)&'P38'!$F4,'P38'!$E4) -> 0 | AR8: =IF('P39'!$E4>"",'P39'!$E4&" "&CHAR(10)&'P39'!$F4,'P39'!$E4) -> 0 | AS8: =IF('P40'!$E4>"",'P40'!$E4&" "&CHAR(10)&'P40'!$F4,'P40'!$E4) -> 0 | AT8: =COUNTIF(F8:AS8,"C*") -> 0 | AU8: =COUNTIF(F8:AS8,"NC*") -> 0 | AV8: =COUNTIF(F8:AS8,"NA*") -> 0 | AW8: =IF(AU8>0,"NC",IF(AT8>0,"C",IF($AV8>0,"NA","NT"))) -> NT | BA8: =IF('P01'!$G4<>"", 'P01'!$G4, "non") -> non | BB8: =IF('P02'!$G4<>"", 'P02'!$G4, "non") -> non | BC8: =IF('P03'!$G4<>"", 'P03'!$G4, "non") -> non | BD8: =IF('P04'!$G4<>"", 'P04'!$G4, "non") -> non | BE8: =IF('P05'!$G4<>"", 'P05'!$G4, "non") -> non | BF8: =IF('P06'!$G4<>"", 'P06'!$G4, "non") -> non | BG8: =IF('P07'!$G4<>"", 'P07'!$G4, "non") -> non | BH8: =IF('P08'!$G4<>"", 'P08'!$G4, "non") -> non | BI8: =IF('P09'!$G4<>"", 'P09'!$G4, "non") -> non | BJ8: =IF('P10'!$G4<>"", 'P10'!$G4, "non") -> non | BK8: =IF('P11'!$G4<>"", 'P11'!$G4, "non") -> non | BL8: =IF('P12'!$G4<>"", 'P12'!$G4, "non") -> non | BM8: =IF('P13'!$G4<>"", 'P13'!$G4, "non") -> non | BN8: =IF('P14'!$G4<>"", 'P14'!$G4, "non") -> non | BO8: =IF('P15'!$G4<>"", 'P15'!$G4, "non") -> non | BP8: =IF('P16'!$G4<>"", 'P16'!$G4, "non") -> non | BQ8: =IF('P17'!$G4<>"", 'P17'!$G4, "non") -> non | BR8: =IF('P18'!$G4<>"", 'P18'!$G4, "non") -> non | BS8: =IF('P19'!$G4<>"", 'P19'!$G4, "non") -> non | BT8: =IF('P20'!$G4<>"", 'P20'!$G4, "non") -> non | BU8: =IF('P21'!$G4<>"", 'P21'!$G4, "non") -> non | BV8: =IF('P22'!$G4<>"", 'P22'!$G4, "non") -> non | BW8: =IF('P23'!$G4<>"", 'P23'!$G4, "non") -> non | BX8: =IF('P24'!$G4<>"", 'P24'!$G4, "non") -> non | BY8: =IF('P25'!$G4<>"", 'P25'!$G4, "non") -> non | BZ8: =IF('P26'!$G4<>"", 'P26'!$G4, "non") -> non | CA8: =IF('P27'!$G4<>"", 'P27'!$G4, "non") -> non | CB8: =IF('P28'!$G4<>"", 'P28'!$G4, "non") -> non | CC8: =IF('P29'!$G4<>"", 'P29'!$G4, "non") -> non | CD8: =IF('P30'!$G4<>"", 'P30'!$G4, "non") -> non | CE8: =IF('P31'!$G4<>"", 'P31'!$G4, "non") -> non | CF8: =IF('P32'!$G4<>"", 'P32'!$G4, "non") -> non | CG8: =IF('P33'!$G4<>"", 'P33'!$G4, "non") -> non | CH8: =IF('P34'!$G4<>"", 'P34'!$G4, "non") -> non | CI8: =IF('P35'!$G4<>"", 'P35'!$G4, "non") -> non | CJ8: =IF('P36'!$G4<>"", 'P36'!$G4, "non") -> non | CK8: =IF('P37'!$G4<>"", 'P37'!$G4, "non") -> non | CL8: =IF('P38'!$G4<>"", 'P38'!$G4, "non") -> non | CM8: =IF('P39'!$G4<>"", 'P39'!$G4, "non") -> non | CN8: =IF('P40'!$G4<>"", 'P40'!$G4, "non") -> non
A9: ='Critères et tests'!B4 -> IMAGES | B9: ='Critères et tests'!$A4 -> 1.2 | C9: =VLOOKUP(B9,'Critères et tests'!$1:$1048576,5,FALSE) -> Chaque image de décoration est-elle correctement ignorée par les technologies d’assistance ? | D9: ='Critères et tests'!$C4 -> A | E9: RGAA | F9: =IF('P01'!$E5>"",'P01'!$E5&" "&CHAR(10)&'P01'!$F5,'P01'!$E5) -> 0 | G9: =IF('P02'!$E5>"",'P02'!$E5&" "&CHAR(10)&'P02'!$F5,'P02'!$E5) -> 0 | H9: =IF('P03'!$E5>"",'P03'!$E5&" "&CHAR(10)&'P03'!$F5,'P03'!$E5) -> 0 | I9: =IF('P04'!$E5>"",'P04'!$E5&" "&CHAR(10)&'P04'!$F5,'P04'!$E5) -> 0 | J9: =IF('P05'!$E5>"",'P05'!$E5&" "&CHAR(10)&'P05'!$F5,'P05'!$E5) -> 0 | K9: =IF('P06'!$E5>"",'P06'!$E5&" "&CHAR(10)&'P06'!$F5,'P06'!$E5) -> 0 | L9: =IF('P07'!$E5>"",'P07'!$E5&" "&CHAR(10)&'P07'!$F5,'P07'!$E5) -> 0 | M9: =IF('P08'!$E5>"",'P08'!$E5&" "&CHAR(10)&'P08'!$F5,'P08'!$E5) -> 0 | N9: =IF('P09'!$E5>"",'P09'!$E5&" "&CHAR(10)&'P09'!$F5,'P09'!$E5) -> 0 | O9: =IF('P10'!$E5>"",'P10'!$E5&" "&CHAR(10)&'P10'!$F5,'P10'!$E5) -> 0 | P9: =IF('P11'!$E5>"",'P11'!$E5&" "&CHAR(10)&'P11'!$F5,'P11'!$E5) -> 0 | Q9: =IF('P12'!$E5>"",'P12'!$E5&" "&CHAR(10)&'P12'!$F5,'P12'!$E5) -> 0 | R9: =IF('P13'!$E5>"",'P13'!$E5&" "&CHAR(10)&'P13'!$F5,'P13'!$E5) -> 0 | S9: =IF('P14'!$E5>"",'P14'!$E5&" "&CHAR(10)&'P14'!$F5,'P14'!$E5) -> 0 | T9: =IF('P15'!$E5>"",'P15'!$E5&" "&CHAR(10)&'P15'!$F5,'P15'!$E5) -> 0 | U9: =IF('P16'!$E5>"",'P16'!$E5&" "&CHAR(10)&'P16'!$F5,'P16'!$E5) -> 0 | V9: =IF('P17'!$E5>"",'P17'!$E5&" "&CHAR(10)&'P17'!$F5,'P17'!$E5) -> 0 | W9: =IF('P18'!$E5>"",'P18'!$E5&" "&CHAR(10)&'P18'!$F5,'P18'!$E5) -> 0 | X9: =IF('P19'!$E5>"",'P19'!$E5&" "&CHAR(10)&'P19'!$F5,'P19'!$E5) -> 0 | Y9: =IF('P20'!$E5>"",'P20'!$E5&" "&CHAR(10)&'P20'!$F5,'P20'!$E5) -> 0 | Z9: =IF('P21'!$E5>"",'P21'!$E5&" "&CHAR(10)&'P21'!$F5,'P21'!$E5) -> 0 | AA9: =IF('P22'!$E5>"",'P22'!$E5&" "&CHAR(10)&'P22'!$F5,'P22'!$E5) -> 0 | AB9: =IF('P23'!$E5>"",'P23'!$E5&" "&CHAR(10)&'P23'!$F5,'P23'!$E5) -> 0 | AC9: =IF('P24'!$E5>"",'P24'!$E5&" "&CHAR(10)&'P24'!$F5,'P24'!$E5) -> 0 | AD9: =IF('P25'!$E5>"",'P25'!$E5&" "&CHAR(10)&'P25'!$F5,'P25'!$E5) -> 0 | AE9: =IF('P26'!$E5>"",'P26'!$E5&" "&CHAR(10)&'P26'!$F5,'P26'!$E5) -> 0 | AF9: =IF('P27'!$E5>"",'P27'!$E5&" "&CHAR(10)&'P27'!$F5,'P27'!$E5) -> 0 | AG9: =IF('P28'!$E5>"",'P28'!$E5&" "&CHAR(10)&'P28'!$F5,'P28'!$E5) -> 0 | AH9: =IF('P29'!$E5>"",'P29'!$E5&" "&CHAR(10)&'P29'!$F5,'P29'!$E5) -> 0 | AI9: =IF('P30'!$E5>"",'P30'!$E5&" "&CHAR(10)&'P30'!$F5,'P30'!$E5) -> 0 | AJ9: =IF('P31'!$E5>"",'P31'!$E5&" "&CHAR(10)&'P31'!$F5,'P31'!$E5) -> 0 | AK9: =IF('P32'!$E5>"",'P32'!$E5&" "&CHAR(10)&'P32'!$F5,'P32'!$E5) -> 0 | AL9: =IF('P33'!$E5>"",'P33'!$E5&" "&CHAR(10)&'P33'!$F5,'P33'!$E5) -> 0 | AM9: =IF('P34'!$E5>"",'P34'!$E5&" "&CHAR(10)&'P34'!$F5,'P34'!$E5) -> 0 | AN9: =IF('P35'!$E5>"",'P35'!$E5&" "&CHAR(10)&'P35'!$F5,'P35'!$E5) -> 0 | AO9: =IF('P36'!$E5>"",'P36'!$E5&" "&CHAR(10)&'P36'!$F5,'P36'!$E5) -> 0 | AP9: =IF('P37'!$E5>"",'P37'!$E5&" "&CHAR(10)&'P37'!$F5,'P37'!$E5) -> 0 | AQ9: =IF('P38'!$E5>"",'P38'!$E5&" "&CHAR(10)&'P38'!$F5,'P38'!$E5) -> 0 | AR9: =IF('P39'!$E5>"",'P39'!$E5&" "&CHAR(10)&'P39'!$F5,'P39'!$E5) -> 0 | AS9: =IF('P40'!$E5>"",'P40'!$E5&" "&CHAR(10)&'P40'!$F5,'P40'!$E5) -> 0 | AT9: =COUNTIF(F9:AS9,"C*") -> 0 | AU9: =COUNTIF(F9:AS9,"NC*") -> 0 | AV9: =COUNTIF(F9:AS9,"NA*") -> 0 | AW9: =IF(AU9>0,"NC",IF(AT9>0,"C",IF($AV9>0,"NA","NT"))) -> NT | BA9: =IF('P01'!$G5<>"", 'P01'!$G5, "non") -> non | BB9: =IF('P02'!$G5<>"", 'P02'!$G5, "non") -> non | BC9: =IF('P03'!$G5<>"", 'P03'!$G5, "non") -> non | BD9: =IF('P04'!$G5<>"", 'P04'!$G5, "non") -> non | BE9: =IF('P05'!$G5<>"", 'P05'!$G5, "non") -> non | BF9: =IF('P06'!$G5<>"", 'P06'!$G5, "non") -> non | BG9: =IF('P07'!$G5<>"", 'P07'!$G5, "non") -> non | BH9: =IF('P08'!$G5<>"", 'P08'!$G5, "non") -> non | BI9: =IF('P09'!$G5<>"", 'P09'!$G5, "non") -> non | BJ9: =IF('P10'!$G5<>"", 'P10'!$G5, "non") -> non | BK9: =IF('P11'!$G5<>"", 'P11'!$G5, "non") -> non | BL9: =IF('P12'!$G5<>"", 'P12'!$G5, "non") -> non | BM9: =IF('P13'!$G5<>"", 'P13'!$G5, "non") -> non | BN9: =IF('P14'!$G5<>"", 'P14'!$G5, "non") -> non | BO9: =IF('P15'!$G5<>"", 'P15'!$G5, "non") -> non | BP9: =IF('P16'!$G5<>"", 'P16'!$G5, "non") -> non | BQ9: =IF('P17'!$G5<>"", 'P17'!$G5, "non") -> non | BR9: =IF('P18'!$G5<>"", 'P18'!$G5, "non") -> non | BS9: =IF('P19'!$G5<>"", 'P19'!$G5, "non") -> non | BT9: =IF('P20'!$G5<>"", 'P20'!$G5, "non") -> non | BU9: =IF('P21'!$G5<>"", 'P21'!$G5, "non") -> non | BV9: =IF('P22'!$G5<>"", 'P22'!$G5, "non") -> non | BW9: =IF('P23'!$G5<>"", 'P23'!$G5, "non") -> non | BX9: =IF('P24'!$G5<>"", 'P24'!$G5, "non") -> non | BY9: =IF('P25'!$G5<>"", 'P25'!$G5, "non") -> non | BZ9: =IF('P26'!$G5<>"", 'P26'!$G5, "non") -> non | CA9: =IF('P27'!$G5<>"", 'P27'!$G5, "non") -> non | CB9: =IF('P28'!$G5<>"", 'P28'!$G5, "non") -> non | CC9: =IF('P29'!$G5<>"", 'P29'!$G5, "non") -> non | CD9: =IF('P30'!$G5<>"", 'P30'!$G5, "non") -> non | CE9: =IF('P31'!$G5<>"", 'P31'!$G5, "non") -> non | CF9: =IF('P32'!$G5<>"", 'P32'!$G5, "non") -> non | CG9: =IF('P33'!$G5<>"", 'P33'!$G5, "non") -> non | CH9: =IF('P34'!$G5<>"", 'P34'!$G5, "non") -> non | CI9: =IF('P35'!$G5<>"", 'P35'!$G5, "non") -> non | CJ9: =IF('P36'!$G5<>"", 'P36'!$G5, "non") -> non | CK9: =IF('P37'!$G5<>"", 'P37'!$G5, "non") -> non | CL9: =IF('P38'!$G5<>"", 'P38'!$G5, "non") -> non | CM9: =IF('P39'!$G5<>"", 'P39'!$G5, "non") -> non | CN9: =IF('P40'!$G5<>"", 'P40'!$G5, "non") -> non
A10: ='Critères et tests'!B5 -> IMAGES | B10: ='Critères et tests'!$A5 -> 1.3 | C10: =VLOOKUP(B10,'Critères et tests'!$1:$1048576,5,FALSE) -> Pour chaque image porteuse d'information ayant une alternative textuelle, cette alternative est-elle pertinente (hors cas particuliers) ? | D10: ='Critères et tests'!$C5 -> A | E10: RGAA | F10: =IF('P01'!$E6>"",'P01'!$E6&" "&CHAR(10)&'P01'!$F6,'P01'!$E6) -> 0 | G10: =IF('P02'!$E6>"",'P02'!$E6&" "&CHAR(10)&'P02'!$F6,'P02'!$E6) -> 0 | H10: =IF('P03'!$E6>"",'P03'!$E6&" "&CHAR(10)&'P03'!$F6,'P03'!$E6) -> 0 | I10: =IF('P04'!$E6>"",'P04'!$E6&" "&CHAR(10)&'P04'!$F6,'P04'!$E6) -> 0 | J10: =IF('P05'!$E6>"",'P05'!$E6&" "&CHAR(10)&'P05'!$F6,'P05'!$E6) -> 0 | K10: =IF('P06'!$E6>"",'P06'!$E6&" "&CHAR(10)&'P06'!$F6,'P06'!$E6) -> 0 | L10: =IF('P07'!$E6>"",'P07'!$E6&" "&CHAR(10)&'P07'!$F6,'P07'!$E6) -> 0 | M10: =IF('P08'!$E6>"",'P08'!$E6&" "&CHAR(10)&'P08'!$F6,'P08'!$E6) -> 0 | N10: =IF('P09'!$E6>"",'P09'!$E6&" "&CHAR(10)&'P09'!$F6,'P09'!$E6) -> 0 | O10: =IF('P10'!$E6>"",'P10'!$E6&" "&CHAR(10)&'P10'!$F6,'P10'!$E6) -> 0 | P10: =IF('P11'!$E6>"",'P11'!$E6&" "&CHAR(10)&'P11'!$F6,'P11'!$E6) -> 0 | Q10: =IF('P12'!$E6>"",'P12'!$E6&" "&CHAR(10)&'P12'!$F6,'P12'!$E6) -> 0 | R10: =IF('P13'!$E6>"",'P13'!$E6&" "&CHAR(10)&'P13'!$F6,'P13'!$E6) -> 0 | S10: =IF('P14'!$E6>"",'P14'!$E6&" "&CHAR(10)&'P14'!$F6,'P14'!$E6) -> 0 | T10: =IF('P15'!$E6>"",'P15'!$E6&" "&CHAR(10)&'P15'!$F6,'P15'!$E6) -> 0 | U10: =IF('P16'!$E6>"",'P16'!$E6&" "&CHAR(10)&'P16'!$F6,'P16'!$E6) -> 0 | V10: =IF('P17'!$E6>"",'P17'!$E6&" "&CHAR(10)&'P17'!$F6,'P17'!$E6) -> 0 | W10: =IF('P18'!$E6>"",'P18'!$E6&" "&CHAR(10)&'P18'!$F6,'P18'!$E6) -> 0 | X10: =IF('P19'!$E6>"",'P19'!$E6&" "&CHAR(10)&'P19'!$F6,'P19'!$E6) -> 0 | Y10: =IF('P20'!$E6>"",'P20'!$E6&" "&CHAR(10)&'P20'!$F6,'P20'!$E6) -> 0 | Z10: =IF('P21'!$E6>"",'P21'!$E6&" "&CHAR(10)&'P21'!$F6,'P21'!$E6) -> 0 | AA10: =IF('P22'!$E6>"",'P22'!$E6&" "&CHAR(10)&'P22'!$F6,'P22'!$E6) -> 0 | AB10: =IF('P23'!$E6>"",'P23'!$E6&" "&CHAR(10)&'P23'!$F6,'P23'!$E6) -> 0 | AC10: =IF('P24'!$E6>"",'P24'!$E6&" "&CHAR(10)&'P24'!$F6,'P24'!$E6) -> 0 | AD10: =IF('P25'!$E6>"",'P25'!$E6&" "&CHAR(10)&'P25'!$F6,'P25'!$E6) -> 0 | AE10: =IF('P26'!$E6>"",'P26'!$E6&" "&CHAR(10)&'P26'!$F6,'P26'!$E6) -> 0 | AF10: =IF('P27'!$E6>"",'P27'!$E6&" "&CHAR(10)&'P27'!$F6,'P27'!$E6) -> 0 | AG10: =IF('P28'!$E6>"",'P28'!$E6&" "&CHAR(10)&'P28'!$F6,'P28'!$E6) -> 0 | AH10: =IF('P29'!$E6>"",'P29'!$E6&" "&CHAR(10)&'P29'!$F6,'P29'!$E6) -> 0 | AI10: =IF('P30'!$E6>"",'P30'!$E6&" "&CHAR(10)&'P30'!$F6,'P30'!$E6) -> 0 | AJ10: =IF('P31'!$E6>"",'P31'!$E6&" "&CHAR(10)&'P31'!$F6,'P31'!$E6) -> 0 | AK10: =IF('P32'!$E6>"",'P32'!$E6&" "&CHAR(10)&'P32'!$F6,'P32'!$E6) -> 0 | AL10: =IF('P33'!$E6>"",'P33'!$E6&" "&CHAR(10)&'P33'!$F6,'P33'!$E6) -> 0 | AM10: =IF('P34'!$E6>"",'P34'!$E6&" "&CHAR(10)&'P34'!$F6,'P34'!$E6) -> 0 | AN10: =IF('P35'!$E6>"",'P35'!$E6&" "&CHAR(10)&'P35'!$F6,'P35'!$E6) -> 0 | AO10: =IF('P36'!$E6>"",'P36'!$E6&" "&CHAR(10)&'P36'!$F6,'P36'!$E6) -> 0 | AP10: =IF('P37'!$E6>"",'P37'!$E6&" "&CHAR(10)&'P37'!$F6,'P37'!$E6) -> 0 | AQ10: =IF('P38'!$E6>"",'P38'!$E6&" "&CHAR(10)&'P38'!$F6,'P38'!$E6) -> 0 | AR10: =IF('P39'!$E6>"",'P39'!$E6&" "&CHAR(10)&'P39'!$F6,'P39'!$E6) -> 0 | AS10: =IF('P40'!$E6>"",'P40'!$E6&" "&CHAR(10)&'P40'!$F6,'P40'!$E6) -> 0 | AT10: =COUNTIF(F10:AS10,"C*") -> 0 | AU10: =COUNTIF(F10:AS10,"NC*") -> 0 | AV10: =COUNTIF(F10:AS10,"NA*") -> 0 | AW10: =IF(AU10>0,"NC",IF(AT10>0,"C",IF($AV10>0,"NA","NT"))) -> NT | BA10: =IF('P01'!$G6<>"", 'P01'!$G6, "non") -> non | BB10: =IF('P02'!$G6<>"", 'P02'!$G6, "non") -> non | BC10: =IF('P03'!$G6<>"", 'P03'!$G6, "non") -> non | BD10: =IF('P04'!$G6<>"", 'P04'!$G6, "non") -> non | BE10: =IF('P05'!$G6<>"", 'P05'!$G6, "non") -> non | BF10: =IF('P06'!$G6<>"", 'P06'!$G6, "non") -> non | BG10: =IF('P07'!$G6<>"", 'P07'!$G6, "non") -> non | BH10: =IF('P08'!$G6<>"", 'P08'!$G6, "non") -> non | BI10: =IF('P09'!$G6<>"", 'P09'!$G6, "non") -> non | BJ10: =IF('P10'!$G6<>"", 'P10'!$G6, "non") -> non | BK10: =IF('P11'!$G6<>"", 'P11'!$G6, "non") -> non | BL10: =IF('P12'!$G6<>"", 'P12'!$G6, "non") -> non | BM10: =IF('P13'!$G6<>"", 'P13'!$G6, "non") -> non | BN10: =IF('P14'!$G6<>"", 'P14'!$G6, "non") -> non | BO10: =IF('P15'!$G6<>"", 'P15'!$G6, "non") -> non | BP10: =IF('P16'!$G6<>"", 'P16'!$G6, "non") -> non | BQ10: =IF('P17'!$G6<>"", 'P17'!$G6, "non") -> non | BR10: =IF('P18'!$G6<>"", 'P18'!$G6, "non") -> non | BS10: =IF('P19'!$G6<>"", 'P19'!$G6, "non") -> non | BT10: =IF('P20'!$G6<>"", 'P20'!$G6, "non") -> non | BU10: =IF('P21'!$G6<>"", 'P21'!$G6, "non") -> non | BV10: =IF('P22'!$G6<>"", 'P22'!$G6, "non") -> non | BW10: =IF('P23'!$G6<>"", 'P23'!$G6, "non") -> non | BX10: =IF('P24'!$G6<>"", 'P24'!$G6, "non") -> non | BY10: =IF('P25'!$G6<>"", 'P25'!$G6, "non") -> non | BZ10: =IF('P26'!$G6<>"", 'P26'!$G6, "non") -> non | CA10: =IF('P27'!$G6<>"", 'P27'!$G6, "non") -> non | CB10: =IF('P28'!$G6<>"", 'P28'!$G6, "non") -> non | CC10: =IF('P29'!$G6<>"", 'P29'!$G6, "non") -> non | CD10: =IF('P30'!$G6<>"", 'P30'!$G6, "non") -> non | CE10: =IF('P31'!$G6<>"", 'P31'!$G6, "non") -> non | CF10: =IF('P32'!$G6<>"", 'P32'!$G6, "non") -> non | CG10: =IF('P33'!$G6<>"", 'P33'!$G6, "non") -> non | CH10: =IF('P34'!$G6<>"", 'P34'!$G6, "non") -> non | CI10: =IF('P35'!$G6<>"", 'P35'!$G6, "non") -> non | CJ10: =IF('P36'!$G6<>"", 'P36'!$G6, "non") -> non | CK10: =IF('P37'!$G6<>"", 'P37'!$G6, "non") -> non | CL10: =IF('P38'!$G6<>"", 'P38'!$G6, "non") -> non | CM10: =IF('P39'!$G6<>"", 'P39'!$G6, "non") -> non | CN10: =IF('P40'!$G6<>"", 'P40'!$G6, "non") -> non
A11: ='Critères et tests'!B6 -> IMAGES | B11: ='Critères et tests'!$A6 -> 1.4 | C11: =VLOOKUP(B11,'Critères et tests'!$1:$1048576,5,FALSE) -> Pour chaque image utilisée comme CAPTCHA ou comme image-test, ayant une alternative textuelle, cette alternative permet-elle d’identifier la nature et la fonction de l’image ? | D11: ='Critères et tests'!$C6 -> A | E11: RGAA | F11: =IF('P01'!$E7>"",'P01'!$E7&" "&CHAR(10)&'P01'!$F7,'P01'!$E7) -> 0 | G11: =IF('P02'!$E7>"",'P02'!$E7&" "&CHAR(10)&'P02'!$F7,'P02'!$E7) -> 0 | H11: =IF('P03'!$E7>"",'P03'!$E7&" "&CHAR(10)&'P03'!$F7,'P03'!$E7) -> 0 | I11: =IF('P04'!$E7>"",'P04'!$E7&" "&CHAR(10)&'P04'!$F7,'P04'!$E7) -> 0 | J11: =IF('P05'!$E7>"",'P05'!$E7&" "&CHAR(10)&'P05'!$F7,'P05'!$E7) -> 0 | K11: =IF('P06'!$E7>"",'P06'!$E7&" "&CHAR(10)&'P06'!$F7,'P06'!$E7) -> 0 | L11: =IF('P07'!$E7>"",'P07'!$E7&" "&CHAR(10)&'P07'!$F7,'P07'!$E7) -> 0 | M11: =IF('P08'!$E7>"",'P08'!$E7&" "&CHAR(10)&'P08'!$F7,'P08'!$E7) -> 0 | N11: =IF('P09'!$E7>"",'P09'!$E7&" "&CHAR(10)&'P09'!$F7,'P09'!$E7) -> 0 | O11: =IF('P10'!$E7>"",'P10'!$E7&" "&CHAR(10)&'P10'!$F7,'P10'!$E7) -> 0 | P11: =IF('P11'!$E7>"",'P11'!$E7&" "&CHAR(10)&'P11'!$F7,'P11'!$E7) -> 0 | Q11: =IF('P12'!$E7>"",'P12'!$E7&" "&CHAR(10)&'P12'!$F7,'P12'!$E7) -> 0 | R11: =IF('P13'!$E7>"",'P13'!$E7&" "&CHAR(10)&'P13'!$F7,'P13'!$E7) -> 0 | S11: =IF('P14'!$E7>"",'P14'!$E7&" "&CHAR(10)&'P14'!$F7,'P14'!$E7) -> 0 | T11: =IF('P15'!$E7>"",'P15'!$E7&" "&CHAR(10)&'P15'!$F7,'P15'!$E7) -> 0 | U11: =IF('P16'!$E7>"",'P16'!$E7&" "&CHAR(10)&'P16'!$F7,'P16'!$E7) -> 0 | V11: =IF('P17'!$E7>"",'P17'!$E7&" "&CHAR(10)&'P17'!$F7,'P17'!$E7) -> 0 | W11: =IF('P18'!$E7>"",'P18'!$E7&" "&CHAR(10)&'P18'!$F7,'P18'!$E7) -> 0 | X11: =IF('P19'!$E7>"",'P19'!$E7&" "&CHAR(10)&'P19'!$F7,'P19'!$E7) -> 0 | Y11: =IF('P20'!$E7>"",'P20'!$E7&" "&CHAR(10)&'P20'!$F7,'P20'!$E7) -> 0 | Z11: =IF('P21'!$E7>"",'P21'!$E7&" "&CHAR(10)&'P21'!$F7,'P21'!$E7) -> 0 | AA11: =IF('P22'!$E7>"",'P22'!$E7&" "&CHAR(10)&'P22'!$F7,'P22'!$E7) -> 0 | AB11: =IF('P23'!$E7>"",'P23'!$E7&" "&CHAR(10)&'P23'!$F7,'P23'!$E7) -> 0 | AC11: =IF('P24'!$E7>"",'P24'!$E7&" "&CHAR(10)&'P24'!$F7,'P24'!$E7) -> 0 | AD11: =IF('P25'!$E7>"",'P25'!$E7&" "&CHAR(10)&'P25'!$F7,'P25'!$E7) -> 0 | AE11: =IF('P26'!$E7>"",'P26'!$E7&" "&CHAR(10)&'P26'!$F7,'P26'!$E7) -> 0 | AF11: =IF('P27'!$E7>"",'P27'!$E7&" "&CHAR(10)&'P27'!$F7,'P27'!$E7) -> 0 | AG11: =IF('P28'!$E7>"",'P28'!$E7&" "&CHAR(10)&'P28'!$F7,'P28'!$E7) -> 0 | AH11: =IF('P29'!$E7>"",'P29'!$E7&" "&CHAR(10)&'P29'!$F7,'P29'!$E7) -> 0 | AI11: =IF('P30'!$E7>"",'P30'!$E7&" "&CHAR(10)&'P30'!$F7,'P30'!$E7) -> 0 | AJ11: =IF('P31'!$E7>"",'P31'!$E7&" "&CHAR(10)&'P31'!$F7,'P31'!$E7) -> 0 | AK11: =IF('P32'!$E7>"",'P32'!$E7&" "&CHAR(10)&'P32'!$F7,'P32'!$E7) -> 0 | AL11: =IF('P33'!$E7>"",'P33'!$E7&" "&CHAR(10)&'P33'!$F7,'P33'!$E7) -> 0 | AM11: =IF('P34'!$E7>"",'P34'!$E7&" "&CHAR(10)&'P34'!$F7,'P34'!$E7) -> 0 | AN11: =IF('P35'!$E7>"",'P35'!$E7&" "&CHAR(10)&'P35'!$F7,'P35'!$E7) -> 0 | AO11: =IF('P36'!$E7>"",'P36'!$E7&" "&CHAR(10)&'P36'!$F7,'P36'!$E7) -> 0 | AP11: =IF('P37'!$E7>"",'P37'!$E7&" "&CHAR(10)&'P37'!$F7,'P37'!$E7) -> 0 | AQ11: =IF('P38'!$E7>"",'P38'!$E7&" "&CHAR(10)&'P38'!$F7,'P38'!$E7) -> 0 | AR11: =IF('P39'!$E7>"",'P39'!$E7&" "&CHAR(10)&'P39'!$F7,'P39'!$E7) -> 0 | AS11: =IF('P40'!$E7>"",'P40'!$E7&" "&CHAR(10)&'P40'!$F7,'P40'!$E7) -> 0 | AT11: =COUNTIF(F11:AS11,"C*") -> 0 | AU11: =COUNTIF(F11:AS11,"NC*") -> 0 | AV11: =COUNTIF(F11:AS11,"NA*") -> 0 | AW11: =IF(AU11>0,"NC",IF(AT11>0,"C",IF($AV11>0,"NA","NT"))) -> NT | BA11: =IF('P01'!$G7<>"", 'P01'!$G7, "non") -> non | BB11: =IF('P02'!$G7<>"", 'P02'!$G7, "non") -> non | BC11: =IF('P03'!$G7<>"", 'P03'!$G7, "non") -> non | BD11: =IF('P04'!$G7<>"", 'P04'!$G7, "non") -> non | BE11: =IF('P05'!$G7<>"", 'P05'!$G7, "non") -> non | BF11: =IF('P06'!$G7<>"", 'P06'!$G7, "non") -> non | BG11: =IF('P07'!$G7<>"", 'P07'!$G7, "non") -> non | BH11: =IF('P08'!$G7<>"", 'P08'!$G7, "non") -> non | BI11: =IF('P09'!$G7<>"", 'P09'!$G7, "non") -> non | BJ11: =IF('P10'!$G7<>"", 'P10'!$G7, "non") -> non | BK11: =IF('P11'!$G7<>"", 'P11'!$G7, "non") -> non | BL11: =IF('P12'!$G7<>"", 'P12'!$G7, "non") -> non | BM11: =IF('P13'!$G7<>"", 'P13'!$G7, "non") -> non | BN11: =IF('P14'!$G7<>"", 'P14'!$G7, "non") -> non | BO11: =IF('P15'!$G7<>"", 'P15'!$G7, "non") -> non | BP11: =IF('P16'!$G7<>"", 'P16'!$G7, "non") -> non | BQ11: =IF('P17'!$G7<>"", 'P17'!$G7, "non") -> non | BR11: =IF('P18'!$G7<>"", 'P18'!$G7, "non") -> non | BS11: =IF('P19'!$G7<>"", 'P19'!$G7, "non") -> non | BT11: =IF('P20'!$G7<>"", 'P20'!$G7, "non") -> non | BU11: =IF('P21'!$G7<>"", 'P21'!$G7, "non") -> non | BV11: =IF('P22'!$G7<>"", 'P22'!$G7, "non") -> non | BW11: =IF('P23'!$G7<>"", 'P23'!$G7, "non") -> non | BX11: =IF('P24'!$G7<>"", 'P24'!$G7, "non") -> non | BY11: =IF('P25'!$G7<>"", 'P25'!$G7, "non") -> non | BZ11: =IF('P26'!$G7<>"", 'P26'!$G7, "non") -> non | CA11: =IF('P27'!$G7<>"", 'P27'!$G7, "non") -> non | CB11: =IF('P28'!$G7<>"", 'P28'!$G7, "non") -> non | CC11: =IF('P29'!$G7<>"", 'P29'!$G7, "non") -> non | CD11: =IF('P30'!$G7<>"", 'P30'!$G7, "non") -> non | CE11: =IF('P31'!$G7<>"", 'P31'!$G7, "non") -> non | CF11: =IF('P32'!$G7<>"", 'P32'!$G7, "non") -> non | CG11: =IF('P33'!$G7<>"", 'P33'!$G7, "non") -> non | CH11: =IF('P34'!$G7<>"", 'P34'!$G7, "non") -> non | CI11: =IF('P35'!$G7<>"", 'P35'!$G7, "non") -> non | CJ11: =IF('P36'!$G7<>"", 'P36'!$G7, "non") -> non | CK11: =IF('P37'!$G7<>"", 'P37'!$G7, "non") -> non | CL11: =IF('P38'!$G7<>"", 'P38'!$G7, "non") -> non | CM11: =IF('P39'!$G7<>"", 'P39'!$G7, "non") -> non | CN11: =IF('P40'!$G7<>"", 'P40'!$G7, "non") -> non
A12: ='Critères et tests'!B7 -> IMAGES | B12: ='Critères et tests'!$A7 -> 1.5 | C12: =VLOOKUP(B12,'Critères et tests'!$1:$1048576,5,FALSE) -> Pour chaque image utilisée comme CAPTCHA, une solution d’accès alternatif au contenu ou à la fonction du CAPTCHA est-elle présente ? | D12: ='Critères et tests'!$C7 -> A | E12: RGAA | F12: =IF('P01'!$E8>"",'P01'!$E8&" "&CHAR(10)&'P01'!$F8,'P01'!$E8) -> 0 | G12: =IF('P02'!$E8>"",'P02'!$E8&" "&CHAR(10)&'P02'!$F8,'P02'!$E8) -> 0 | H12: =IF('P03'!$E8>"",'P03'!$E8&" "&CHAR(10)&'P03'!$F8,'P03'!$E8) -> 0 | I12: =IF('P04'!$E8>"",'P04'!$E8&" "&CHAR(10)&'P04'!$F8,'P04'!$E8) -> 0 | J12: =IF('P05'!$E8>"",'P05'!$E8&" "&CHAR(10)&'P05'!$F8,'P05'!$E8) -> 0 | K12: =IF('P06'!$E8>"",'P06'!$E8&" "&CHAR(10)&'P06'!$F8,'P06'!$E8) -> 0 | L12: =IF('P07'!$E8>"",'P07'!$E8&" "&CHAR(10)&'P07'!$F8,'P07'!$E8) -> 0 | M12: =IF('P08'!$E8>"",'P08'!$E8&" "&CHAR(10)&'P08'!$F8,'P08'!$E8) -> 0 | N12: =IF('P09'!$E8>"",'P09'!$E8&" "&CHAR(10)&'P09'!$F8,'P09'!$E8) -> 0 | O12: =IF('P10'!$E8>"",'P10'!$E8&" "&CHAR(10)&'P10'!$F8,'P10'!$E8) -> 0 | P12: =IF('P11'!$E8>"",'P11'!$E8&" "&CHAR(10)&'P11'!$F8,'P11'!$E8) -> 0 | Q12: =IF('P12'!$E8>"",'P12'!$E8&" "&CHAR(10)&'P12'!$F8,'P12'!$E8) -> 0 | R12: =IF('P13'!$E8>"",'P13'!$E8&" "&CHAR(10)&'P13'!$F8,'P13'!$E8) -> 0 | S12: =IF('P14'!$E8>"",'P14'!$E8&" "&CHAR(10)&'P14'!$F8,'P14'!$E8) -> 0 | T12: =IF('P15'!$E8>"",'P15'!$E8&" "&CHAR(10)&'P15'!$F8,'P15'!$E8) -> 0 | U12: =IF('P16'!$E8>"",'P16'!$E8&" "&CHAR(10)&'P16'!$F8,'P16'!$E8) -> 0 | V12: =IF('P17'!$E8>"",'P17'!$E8&" "&CHAR(10)&'P17'!$F8,'P17'!$E8) -> 0 | W12: =IF('P18'!$E8>"",'P18'!$E8&" "&CHAR(10)&'P18'!$F8,'P18'!$E8) -> 0 | X12: =IF('P19'!$E8>"",'P19'!$E8&" "&CHAR(10)&'P19'!$F8,'P19'!$E8) -> 0 | Y12: =IF('P20'!$E8>"",'P20'!$E8&" "&CHAR(10)&'P20'!$F8,'P20'!$E8) -> 0 | Z12: =IF('P21'!$E8>"",'P21'!$E8&" "&CHAR(10)&'P21'!$F8,'P21'!$E8) -> 0 | AA12: =IF('P22'!$E8>"",'P22'!$E8&" "&CHAR(10)&'P22'!$F8,'P22'!$E8) -> 0 | AB12: =IF('P23'!$E8>"",'P23'!$E8&" "&CHAR(10)&'P23'!$F8,'P23'!$E8) -> 0 | AC12: =IF('P24'!$E8>"",'P24'!$E8&" "&CHAR(10)&'P24'!$F8,'P24'!$E8) -> 0 | AD12: =IF('P25'!$E8>"",'P25'!$E8&" "&CHAR(10)&'P25'!$F8,'P25'!$E8) -> 0 | AE12: =IF('P26'!$E8>"",'P26'!$E8&" "&CHAR(10)&'P26'!$F8,'P26'!$E8) -> 0 | AF12: =IF('P27'!$E8>"",'P27'!$E8&" "&CHAR(10)&'P27'!$F8,'P27'!$E8) -> 0 | AG12: =IF('P28'!$E8>"",'P28'!$E8&" "&CHAR(10)&'P28'!$F8,'P28'!$E8) -> 0 | AH12: =IF('P29'!$E8>"",'P29'!$E8&" "&CHAR(10)&'P29'!$F8,'P29'!$E8) -> 0 | AI12: =IF('P30'!$E8>"",'P30'!$E8&" "&CHAR(10)&'P30'!$F8,'P30'!$E8) -> 0 | AJ12: =IF('P31'!$E8>"",'P31'!$E8&" "&CHAR(10)&'P31'!$F8,'P31'!$E8) -> 0 | AK12: =IF('P32'!$E8>"",'P32'!$E8&" "&CHAR(10)&'P32'!$F8,'P32'!$E8) -> 0 | AL12: =IF('P33'!$E8>"",'P33'!$E8&" "&CHAR(10)&'P33'!$F8,'P33'!$E8) -> 0 | AM12: =IF('P34'!$E8>"",'P34'!$E8&" "&CHAR(10)&'P34'!$F8,'P34'!$E8) -> 0 | AN12: =IF('P35'!$E8>"",'P35'!$E8&" "&CHAR(10)&'P35'!$F8,'P35'!$E8) -> 0 | AO12: =IF('P36'!$E8>"",'P36'!$E8&" "&CHAR(10)&'P36'!$F8,'P36'!$E8) -> 0 | AP12: =IF('P37'!$E8>"",'P37'!$E8&" "&CHAR(10)&'P37'!$F8,'P37'!$E8) -> 0 | AQ12: =IF('P38'!$E8>"",'P38'!$E8&" "&CHAR(10)&'P38'!$F8,'P38'!$E8) -> 0 | AR12: =IF('P39'!$E8>"",'P39'!$E8&" "&CHAR(10)&'P39'!$F8,'P39'!$E8) -> 0 | AS12: =IF('P40'!$E8>"",'P40'!$E8&" "&CHAR(10)&'P40'!$F8,'P40'!$E8) -> 0 | AT12: =COUNTIF(F12:AS12,"C*") -> 0 | AU12: =COUNTIF(F12:AS12,"NC*") -> 0 | AV12: =COUNTIF(F12:AS12,"NA*") -> 0 | AW12: =IF(AU12>0,"NC",IF(AT12>0,"C",IF($AV12>0,"NA","NT"))) -> NT | BA12: =IF('P01'!$G8<>"", 'P01'!$G8, "non") -> non | BB12: =IF('P02'!$G8<>"", 'P02'!$G8, "non") -> non | BC12: =IF('P03'!$G8<>"", 'P03'!$G8, "non") -> non | BD12: =IF('P04'!$G8<>"", 'P04'!$G8, "non") -> non | BE12: =IF('P05'!$G8<>"", 'P05'!$G8, "non") -> non | BF12: =IF('P06'!$G8<>"", 'P06'!$G8, "non") -> non | BG12: =IF('P07'!$G8<>"", 'P07'!$G8, "non") -> non | BH12: =IF('P08'!$G8<>"", 'P08'!$G8, "non") -> non | BI12: =IF('P09'!$G8<>"", 'P09'!$G8, "non") -> non | BJ12: =IF('P10'!$G8<>"", 'P10'!$G8, "non") -> non | BK12: =IF('P11'!$G8<>"", 'P11'!$G8, "non") -> non | BL12: =IF('P12'!$G8<>"", 'P12'!$G8, "non") -> non | BM12: =IF('P13'!$G8<>"", 'P13'!$G8, "non") -> non | BN12: =IF('P14'!$G8<>"", 'P14'!$G8, "non") -> non | BO12: =IF('P15'!$G8<>"", 'P15'!$G8, "non") -> non | BP12: =IF('P16'!$G8<>"", 'P16'!$G8, "non") -> non | BQ12: =IF('P17'!$G8<>"", 'P17'!$G8, "non") -> non | BR12: =IF('P18'!$G8<>"", 'P18'!$G8, "non") -> non | BS12: =IF('P19'!$G8<>"", 'P19'!$G8, "non") -> non | BT12: =IF('P20'!$G8<>"", 'P20'!$G8, "non") -> non | BU12: =IF('P21'!$G8<>"", 'P21'!$G8, "non") -> non | BV12: =IF('P22'!$G8<>"", 'P22'!$G8, "non") -> non | BW12: =IF('P23'!$G8<>"", 'P23'!$G8, "non") -> non | BX12: =IF('P24'!$G8<>"", 'P24'!$G8, "non") -> non | BY12: =IF('P25'!$G8<>"", 'P25'!$G8, "non") -> non | BZ12: =IF('P26'!$G8<>"", 'P26'!$G8, "non") -> non | CA12: =IF('P27'!$G8<>"", 'P27'!$G8, "non") -> non | CB12: =IF('P28'!$G8<>"", 'P28'!$G8, "non") -> non | CC12: =IF('P29'!$G8<>"", 'P29'!$G8, "non") -> non | CD12: =IF('P30'!$G8<>"", 'P30'!$G8, "non") -> non | CE12: =IF('P31'!$G8<>"", 'P31'!$G8, "non") -> non | CF12: =IF('P32'!$G8<>"", 'P32'!$G8, "non") -> non | CG12: =IF('P33'!$G8<>"", 'P33'!$G8, "non") -> non | CH12: =IF('P34'!$G8<>"", 'P34'!$G8, "non") -> non | CI12: =IF('P35'!$G8<>"", 'P35'!$G8, "non") -> non | CJ12: =IF('P36'!$G8<>"", 'P36'!$G8, "non") -> non | CK12: =IF('P37'!$G8<>"", 'P37'!$G8, "non") -> non | CL12: =IF('P38'!$G8<>"", 'P38'!$G8, "non") -> non | CM12: =IF('P39'!$G8<>"", 'P39'!$G8, "non") -> non | CN12: =IF('P40'!$G8<>"", 'P40'!$G8, "non") -> non
A13: ='Critères et tests'!B8 -> IMAGES | B13: ='Critères et tests'!$A8 -> 1.6 | C13: =VLOOKUP(B13,'Critères et tests'!$1:$1048576,5,FALSE) -> Chaque image porteuse d’information a-t-elle, si nécessaire, une description détaillée ? | D13: ='Critères et tests'!$C8 -> A | E13: RGAA | F13: =IF('P01'!$E9>"",'P01'!$E9&" "&CHAR(10)&'P01'!$F9,'P01'!$E9) -> 0 | G13: =IF('P02'!$E9>"",'P02'!$E9&" "&CHAR(10)&'P02'!$F9,'P02'!$E9) -> 0 | H13: =IF('P03'!$E9>"",'P03'!$E9&" "&CHAR(10)&'P03'!$F9,'P03'!$E9) -> 0 | I13: =IF('P04'!$E9>"",'P04'!$E9&" "&CHAR(10)&'P04'!$F9,'P04'!$E9) -> 0 | J13: =IF('P05'!$E9>"",'P05'!$E9&" "&CHAR(10)&'P05'!$F9,'P05'!$E9) -> 0 | K13: =IF('P06'!$E9>"",'P06'!$E9&" "&CHAR(10)&'P06'!$F9,'P06'!$E9) -> 0 | L13: =IF('P07'!$E9>"",'P07'!$E9&" "&CHAR(10)&'P07'!$F9,'P07'!$E9) -> 0 | M13: =IF('P08'!$E9>"",'P08'!$E9&" "&CHAR(10)&'P08'!$F9,'P08'!$E9) -> 0 | N13: =IF('P09'!$E9>"",'P09'!$E9&" "&CHAR(10)&'P09'!$F9,'P09'!$E9) -> 0 | O13: =IF('P10'!$E9>"",'P10'!$E9&" "&CHAR(10)&'P10'!$F9,'P10'!$E9) -> 0 | P13: =IF('P11'!$E9>"",'P11'!$E9&" "&CHAR(10)&'P11'!$F9,'P11'!$E9) -> 0 | Q13: =IF('P12'!$E9>"",'P12'!$E9&" "&CHAR(10)&'P12'!$F9,'P12'!$E9) -> 0 | R13: =IF('P13'!$E9>"",'P13'!$E9&" "&CHAR(10)&'P13'!$F9,'P13'!$E9) -> 0 | S13: =IF('P14'!$E9>"",'P14'!$E9&" "&CHAR(10)&'P14'!$F9,'P14'!$E9) -> 0 | T13: =IF('P15'!$E9>"",'P15'!$E9&" "&CHAR(10)&'P15'!$F9,'P15'!$E9) -> 0 | U13: =IF('P16'!$E9>"",'P16'!$E9&" "&CHAR(10)&'P16'!$F9,'P16'!$E9) -> 0 | V13: =IF('P17'!$E9>"",'P17'!$E9&" "&CHAR(10)&'P17'!$F9,'P17'!$E9) -> 0 | W13: =IF('P18'!$E9>"",'P18'!$E9&" "&CHAR(10)&'P18'!$F9,'P18'!$E9) -> 0 | X13: =IF('P19'!$E9>"",'P19'!$E9&" "&CHAR(10)&'P19'!$F9,'P19'!$E9) -> 0 | Y13: =IF('P20'!$E9>"",'P20'!$E9&" "&CHAR(10)&'P20'!$F9,'P20'!$E9) -> 0 | Z13: =IF('P21'!$E9>"",'P21'!$E9&" "&CHAR(10)&'P21'!$F9,'P21'!$E9) -> 0 | AA13: =IF('P22'!$E9>"",'P22'!$E9&" "&CHAR(10)&'P22'!$F9,'P22'!$E9) -> 0 | AB13: =IF('P23'!$E9>"",'P23'!$E9&" "&CHAR(10)&'P23'!$F9,'P23'!$E9) -> 0 | AC13: =IF('P24'!$E9>"",'P24'!$E9&" "&CHAR(10)&'P24'!$F9,'P24'!$E9) -> 0 | AD13: =IF('P25'!$E9>"",'P25'!$E9&" "&CHAR(10)&'P25'!$F9,'P25'!$E9) -> 0 | AE13: =IF('P26'!$E9>"",'P26'!$E9&" "&CHAR(10)&'P26'!$F9,'P26'!$E9) -> 0 | AF13: =IF('P27'!$E9>"",'P27'!$E9&" "&CHAR(10)&'P27'!$F9,'P27'!$E9) -> 0 | AG13: =IF('P28'!$E9>"",'P28'!$E9&" "&CHAR(10)&'P28'!$F9,'P28'!$E9) -> 0 | AH13: =IF('P29'!$E9>"",'P29'!$E9&" "&CHAR(10)&'P29'!$F9,'P29'!$E9) -> 0 | AI13: =IF('P30'!$E9>"",'P30'!$E9&" "&CHAR(10)&'P30'!$F9,'P30'!$E9) -> 0 | AJ13: =IF('P31'!$E9>"",'P31'!$E9&" "&CHAR(10)&'P31'!$F9,'P31'!$E9) -> 0 | AK13: =IF('P32'!$E9>"",'P32'!$E9&" "&CHAR(10)&'P32'!$F9,'P32'!$E9) -> 0 | AL13: =IF('P33'!$E9>"",'P33'!$E9&" "&CHAR(10)&'P33'!$F9,'P33'!$E9) -> 0 | AM13: =IF('P34'!$E9>"",'P34'!$E9&" "&CHAR(10)&'P34'!$F9,'P34'!$E9) -> 0 | AN13: =IF('P35'!$E9>"",'P35'!$E9&" "&CHAR(10)&'P35'!$F9,'P35'!$E9) -> 0 | AO13: =IF('P36'!$E9>"",'P36'!$E9&" "&CHAR(10)&'P36'!$F9,'P36'!$E9) -> 0 | AP13: =IF('P37'!$E9>"",'P37'!$E9&" "&CHAR(10)&'P37'!$F9,'P37'!$E9) -> 0 | AQ13: =IF('P38'!$E9>"",'P38'!$E9&" "&CHAR(10)&'P38'!$F9,'P38'!$E9) -> 0 | AR13: =IF('P39'!$E9>"",'P39'!$E9&" "&CHAR(10)&'P39'!$F9,'P39'!$E9) -> 0 | AS13: =IF('P40'!$E9>"",'P40'!$E9&" "&CHAR(10)&'P40'!$F9,'P40'!$E9) -> 0 | AT13: =COUNTIF(F13:AS13,"C*") -> 0 | AU13: =COUNTIF(F13:AS13,"NC*") -> 0 | AV13: =COUNTIF(F13:AS13,"NA*") -> 0 | AW13: =IF(AU13>0,"NC",IF(AT13>0,"C",IF($AV13>0,"NA","NT"))) -> NT | BA13: =IF('P01'!$G9<>"", 'P01'!$G9, "non") -> non | BB13: =IF('P02'!$G9<>"", 'P02'!$G9, "non") -> non | BC13: =IF('P03'!$G9<>"", 'P03'!$G9, "non") -> non | BD13: =IF('P04'!$G9<>"", 'P04'!$G9, "non") -> non | BE13: =IF('P05'!$G9<>"", 'P05'!$G9, "non") -> non | BF13: =IF('P06'!$G9<>"", 'P06'!$G9, "non") -> non | BG13: =IF('P07'!$G9<>"", 'P07'!$G9, "non") -> non | BH13: =IF('P08'!$G9<>"", 'P08'!$G9, "non") -> non | BI13: =IF('P09'!$G9<>"", 'P09'!$G9, "non") -> non | BJ13: =IF('P10'!$G9<>"", 'P10'!$G9, "non") -> non | BK13: =IF('P11'!$G9<>"", 'P11'!$G9, "non") -> non | BL13: =IF('P12'!$G9<>"", 'P12'!$G9, "non") -> non | BM13: =IF('P13'!$G9<>"", 'P13'!$G9, "non") -> non | BN13: =IF('P14'!$G9<>"", 'P14'!$G9, "non") -> non | BO13: =IF('P15'!$G9<>"", 'P15'!$G9, "non") -> non | BP13: =IF('P16'!$G9<>"", 'P16'!$G9, "non") -> non | BQ13: =IF('P17'!$G9<>"", 'P17'!$G9, "non") -> non | BR13: =IF('P18'!$G9<>"", 'P18'!$G9, "non") -> non | BS13: =IF('P19'!$G9<>"", 'P19'!$G9, "non") -> non | BT13: =IF('P20'!$G9<>"", 'P20'!$G9, "non") -> non | BU13: =IF('P21'!$G9<>"", 'P21'!$G9, "non") -> non | BV13: =IF('P22'!$G9<>"", 'P22'!$G9, "non") -> non | BW13: =IF('P23'!$G9<>"", 'P23'!$G9, "non") -> non | BX13: =IF('P24'!$G9<>"", 'P24'!$G9, "non") -> non | BY13: =IF('P25'!$G9<>"", 'P25'!$G9, "non") -> non | BZ13: =IF('P26'!$G9<>"", 'P26'!$G9, "non") -> non | CA13: =IF('P27'!$G9<>"", 'P27'!$G9, "non") -> non | CB13: =IF('P28'!$G9<>"", 'P28'!$G9, "non") -> non | CC13: =IF('P29'!$G9<>"", 'P29'!$G9, "non") -> non | CD13: =IF('P30'!$G9<>"", 'P30'!$G9, "non") -> non | CE13: =IF('P31'!$G9<>"", 'P31'!$G9, "non") -> non | CF13: =IF('P32'!$G9<>"", 'P32'!$G9, "non") -> non | CG13: =IF('P33'!$G9<>"", 'P33'!$G9, "non") -> non | CH13: =IF('P34'!$G9<>"", 'P34'!$G9, "non") -> non | CI13: =IF('P35'!$G9<>"", 'P35'!$G9, "non") -> non | CJ13: =IF('P36'!$G9<>"", 'P36'!$G9, "non") -> non | CK13: =IF('P37'!$G9<>"", 'P37'!$G9, "non") -> non | CL13: =IF('P38'!$G9<>"", 'P38'!$G9, "non") -> non | CM13: =IF('P39'!$G9<>"", 'P39'!$G9, "non") -> non | CN13: =IF('P40'!$G9<>"", 'P40'!$G9, "non") -> non
